2020-10-25 20:07:53,878 - admin - DEBUG -scripts.utils - b'#!/bin/sh\n'
2020-10-25 20:07:53,878 - admin - DEBUG -scripts.utils - b'\n'
2020-10-25 20:07:53,878 - admin - DEBUG -scripts.utils - b'echo "Test passed 1"\n'
2020-10-25 20:07:53,879 - admin - DEBUG -scripts.utils - b"+ echo 'Test passed 1'\n"
2020-10-25 20:07:53,879 - admin - DEBUG -scripts.utils - b'\n'
2020-10-25 20:07:53,879 - admin - DEBUG -scripts.utils - b'fname=$1\n'
2020-10-25 20:07:53,879 - admin - DEBUG -scripts.utils - b'+ fname=1\n'
2020-10-25 20:07:53,879 - admin - DEBUG -scripts.utils - b'lname=$2\n'
2020-10-25 20:07:53,880 - admin - DEBUG -scripts.utils - b'+ lname=2\n'
2020-10-25 20:07:53,880 - admin - DEBUG -scripts.utils - b'num=$3\n'
2020-10-25 20:07:53,880 - admin - DEBUG -scripts.utils - b'+ num=3\n'
2020-10-25 20:07:53,880 - admin - DEBUG -scripts.utils - b'echo "fame=${fname}"\n'
2020-10-25 20:07:53,880 - admin - DEBUG -scripts.utils - b'+ echo fame=1\n'
2020-10-25 20:07:53,881 - admin - DEBUG -scripts.utils - b'echo "lname=${lname}"\n'
2020-10-25 20:07:53,881 - admin - DEBUG -scripts.utils - b'+ echo lname=2\n'
2020-10-25 20:07:53,881 - admin - DEBUG -scripts.utils - b'echo "num=${num}"\n'
2020-10-25 20:07:53,881 - admin - DEBUG -scripts.utils - b'+ echo num=3\n'
2020-10-25 20:07:53,881 - admin - DEBUG -scripts.utils - b'\n'
2020-10-25 20:07:53,882 - admin - DEBUG -scripts.utils - b'x=1\n'
2020-10-25 20:07:53,882 - admin - DEBUG -scripts.utils - b'+ x=1\n'
2020-10-25 20:07:53,882 - admin - DEBUG -scripts.utils - b'y=2\n'
2020-10-25 20:07:53,882 - admin - DEBUG -scripts.utils - b'+ y=2\n'
2020-10-25 20:07:53,883 - admin - DEBUG -scripts.utils - b'\n'
2020-10-25 20:07:53,883 - admin - DEBUG -scripts.utils - b'\n'
2020-10-25 20:07:53,883 - admin - DEBUG -scripts.utils - b'sleep 2;\n'
2020-10-25 20:07:53,883 - admin - DEBUG -scripts.utils - b'+ sleep 2\n'
2020-10-25 20:07:55,884 - admin - DEBUG -scripts.utils - b'\n'
2020-10-25 20:07:55,885 - admin - DEBUG -scripts.utils - b'\n'
2020-10-25 20:07:55,885 - admin - DEBUG -scripts.utils - b'\n'
2020-10-25 20:07:55,886 - admin - DEBUG -scripts.utils - b'# exit 7\n'
2020-10-25 20:07:55,886 - admin - DEBUG -scripts.utils - b'\n'
2020-10-25 20:07:55,886 - admin - DEBUG -scripts.utils - b'# echo "Arjun" > /Users/arjunkumar/Desktop/notes2/pre-prod/front_end/PyDataFlow_Local/PyDataFlow/pydataflow/logs/2019-08-20/mlab_adhoc/log.txt\n'
2020-10-25 20:07:55,886 - admin - DEBUG -scripts.utils - b'\n'
2020-10-25 20:07:56,151 - admin - ERROR -scripts.utils - scripts:util:exe_script_util:process_id: Fatal error:Unable to execute the script:sh -xv /Users/arjunkumar/Desktop/notes2/pre-prod/front_end/PyDataFlow_Local/PyDataFlow/pydataflow/core/test.sh, with params:1 2 3 for detail, Please refer to logfile:/Users/arjunkumar/Desktop/notes2/pre-prod/front_end/PyDataFlow_Local/PyDataFlow/pydataflow/logs/2020-10-25/test_migration/5051_38208_test0_2020-10-25-20:07:52.log 
Traceback (most recent call last):
  File "/Users/arjunkumar/Desktop/notes2/pre-prod/front_end/PyDataFlow_Local/PyDataFlow/pydataflow/scripts/utils.py", line 131, in exe_script_util
    email_notification_job(msg, process_id, **Jobflowdetail_d)
  File "/Users/arjunkumar/Desktop/notes2/pre-prod/front_end/PyDataFlow_Local/PyDataFlow/pydataflow/meta/utils.py", line 1057, in email_notification_job
    send_mail_func(subject, message, from_email, recipient_list)
  File "/Users/arjunkumar/Desktop/notes2/pre-prod/front_end/PyDataFlow_Local/PyDataFlow/pydataflow/meta/utils.py", line 1067, in send_mail_func
    html_message=None)
  File "/Users/arjunkumar/Desktop/notes2/pre-prod/front_end/PyDataFlow_Local/PyDataFlow/lib/python3.7/site-packages/django/core/mail/__init__.py", line 60, in send_mail
    return mail.send()
  File "/Users/arjunkumar/Desktop/notes2/pre-prod/front_end/PyDataFlow_Local/PyDataFlow/lib/python3.7/site-packages/django/core/mail/message.py", line 291, in send
    return self.get_connection(fail_silently).send_messages([self])
  File "/Users/arjunkumar/Desktop/notes2/pre-prod/front_end/PyDataFlow_Local/PyDataFlow/lib/python3.7/site-packages/django/core/mail/backends/smtp.py", line 103, in send_messages
    new_conn_created = self.open()
  File "/Users/arjunkumar/Desktop/notes2/pre-prod/front_end/PyDataFlow_Local/PyDataFlow/lib/python3.7/site-packages/django/core/mail/backends/smtp.py", line 63, in open
    self.connection = self.connection_class(self.host, self.port, **connection_params)
  File "/usr/local/Cellar/python/3.7.6_1/Frameworks/Python.framework/Versions/3.7/lib/python3.7/smtplib.py", line 251, in __init__
    (code, msg) = self.connect(host, port)
  File "/usr/local/Cellar/python/3.7.6_1/Frameworks/Python.framework/Versions/3.7/lib/python3.7/smtplib.py", line 336, in connect
    self.sock = self._get_socket(host, port, self.timeout)
  File "/usr/local/Cellar/python/3.7.6_1/Frameworks/Python.framework/Versions/3.7/lib/python3.7/smtplib.py", line 307, in _get_socket
    self.source_address)
  File "/usr/local/Cellar/python/3.7.6_1/Frameworks/Python.framework/Versions/3.7/lib/python3.7/socket.py", line 728, in create_connection
    raise err
  File "/usr/local/Cellar/python/3.7.6_1/Frameworks/Python.framework/Versions/3.7/lib/python3.7/socket.py", line 716, in create_connection
    sock.connect(sa)
ConnectionRefusedError: [Errno 61] Connection refused
2020-10-25 20:07:56,151 - admin - ERROR -scripts.utils - scripts:util:exe_script_util:process_id: Fatal error:Unable to execute the script:sh -xv /Users/arjunkumar/Desktop/notes2/pre-prod/front_end/PyDataFlow_Local/PyDataFlow/pydataflow/core/test.sh, with params:1 2 3 for detail, Please refer to logfile:/Users/arjunkumar/Desktop/notes2/pre-prod/front_end/PyDataFlow_Local/PyDataFlow/pydataflow/logs/2020-10-25/test_migration/5051_38208_test0_2020-10-25-20:07:52.log 
Traceback (most recent call last):
  File "/Users/arjunkumar/Desktop/notes2/pre-prod/front_end/PyDataFlow_Local/PyDataFlow/pydataflow/scripts/utils.py", line 131, in exe_script_util
    email_notification_job(msg, process_id, **Jobflowdetail_d)
  File "/Users/arjunkumar/Desktop/notes2/pre-prod/front_end/PyDataFlow_Local/PyDataFlow/pydataflow/meta/utils.py", line 1057, in email_notification_job
    send_mail_func(subject, message, from_email, recipient_list)
  File "/Users/arjunkumar/Desktop/notes2/pre-prod/front_end/PyDataFlow_Local/PyDataFlow/pydataflow/meta/utils.py", line 1067, in send_mail_func
    html_message=None)
  File "/Users/arjunkumar/Desktop/notes2/pre-prod/front_end/PyDataFlow_Local/PyDataFlow/lib/python3.7/site-packages/django/core/mail/__init__.py", line 60, in send_mail
    return mail.send()
  File "/Users/arjunkumar/Desktop/notes2/pre-prod/front_end/PyDataFlow_Local/PyDataFlow/lib/python3.7/site-packages/django/core/mail/message.py", line 291, in send
    return self.get_connection(fail_silently).send_messages([self])
  File "/Users/arjunkumar/Desktop/notes2/pre-prod/front_end/PyDataFlow_Local/PyDataFlow/lib/python3.7/site-packages/django/core/mail/backends/smtp.py", line 103, in send_messages
    new_conn_created = self.open()
  File "/Users/arjunkumar/Desktop/notes2/pre-prod/front_end/PyDataFlow_Local/PyDataFlow/lib/python3.7/site-packages/django/core/mail/backends/smtp.py", line 63, in open
    self.connection = self.connection_class(self.host, self.port, **connection_params)
  File "/usr/local/Cellar/python/3.7.6_1/Frameworks/Python.framework/Versions/3.7/lib/python3.7/smtplib.py", line 251, in __init__
    (code, msg) = self.connect(host, port)
  File "/usr/local/Cellar/python/3.7.6_1/Frameworks/Python.framework/Versions/3.7/lib/python3.7/smtplib.py", line 336, in connect
    self.sock = self._get_socket(host, port, self.timeout)
  File "/usr/local/Cellar/python/3.7.6_1/Frameworks/Python.framework/Versions/3.7/lib/python3.7/smtplib.py", line 307, in _get_socket
    self.source_address)
  File "/usr/local/Cellar/python/3.7.6_1/Frameworks/Python.framework/Versions/3.7/lib/python3.7/socket.py", line 728, in create_connection
    raise err
  File "/usr/local/Cellar/python/3.7.6_1/Frameworks/Python.framework/Versions/3.7/lib/python3.7/socket.py", line 716, in create_connection
    sock.connect(sa)
ConnectionRefusedError: [Errno 61] Connection refused
