2020-10-23 00:49:40,164 - admin - DEBUG -scripts.utils - b'#!/bin/sh\n'
2020-10-23 00:49:40,165 - admin - DEBUG -scripts.utils - b'\n'
2020-10-23 00:49:40,165 - admin - DEBUG -scripts.utils - b'echo "Test passed"\n'
2020-10-23 00:49:40,165 - admin - DEBUG -scripts.utils - b"+ echo 'Test passed'\n"
2020-10-23 00:49:40,166 - admin - DEBUG -scripts.utils - b'\n'
2020-10-23 00:49:40,166 - admin - DEBUG -scripts.utils - b'fname=$1\n'
2020-10-23 00:49:40,166 - admin - DEBUG -scripts.utils - b'+ fname=5\n'
2020-10-23 00:49:40,166 - admin - DEBUG -scripts.utils - b'lname=$2\n'
2020-10-23 00:49:40,167 - admin - DEBUG -scripts.utils - b'+ lname=6\n'
2020-10-23 00:49:40,167 - admin - DEBUG -scripts.utils - b'num=$3\n'
2020-10-23 00:49:40,167 - admin - DEBUG -scripts.utils - b'+ num=7\n'
2020-10-23 00:49:40,168 - admin - DEBUG -scripts.utils - b'echo "fame=${fname}"\n'
2020-10-23 00:49:40,168 - admin - DEBUG -scripts.utils - b'+ echo fame=5\n'
2020-10-23 00:49:40,169 - admin - DEBUG -scripts.utils - b'echo "lname=${lname}"\n'
2020-10-23 00:49:40,169 - admin - DEBUG -scripts.utils - b'+ echo lname=6\n'
2020-10-23 00:49:40,169 - admin - DEBUG -scripts.utils - b'echo "num=${num}"\n'
2020-10-23 00:49:40,170 - admin - DEBUG -scripts.utils - b'+ echo num=7\n'
2020-10-23 00:49:40,170 - admin - DEBUG -scripts.utils - b'\n'
2020-10-23 00:49:40,170 - admin - DEBUG -scripts.utils - b'x=1\n'
2020-10-23 00:49:40,171 - admin - DEBUG -scripts.utils - b'+ x=1\n'
2020-10-23 00:49:40,171 - admin - DEBUG -scripts.utils - b'y=2\n'
2020-10-23 00:49:40,171 - admin - DEBUG -scripts.utils - b'+ y=2\n'
2020-10-23 00:49:40,171 - admin - DEBUG -scripts.utils - b'\n'
2020-10-23 00:49:40,172 - admin - DEBUG -scripts.utils - b'\n'
2020-10-23 00:49:40,172 - admin - DEBUG -scripts.utils - b'sleep 2;\n'
2020-10-23 00:49:40,172 - admin - DEBUG -scripts.utils - b'+ sleep 2\n'
2020-10-23 00:49:42,169 - admin - DEBUG -scripts.utils - b'exit 9\n'
2020-10-23 00:49:42,169 - admin - DEBUG -scripts.utils - b'+ exit 9\n'
2020-10-23 00:49:42,170 - admin - ERROR -scripts.utils - scripts:util:exe_script_util:process_id: Warning::Unable to execute the script:sh -xv /Users/arjunkumar/Desktop/notes2/pre-prod/front_end/PyDataFlow_Local/PyDataFlow/pydataflow/core/test3.sh, with params:5 6 7 
NoneType: None
2020-10-23 00:49:42,170 - admin - ERROR -scripts.utils - scripts:util:exe_script_util:process_id: Warning::Unable to execute the script:sh -xv /Users/arjunkumar/Desktop/notes2/pre-prod/front_end/PyDataFlow_Local/PyDataFlow/pydataflow/core/test3.sh, with params:5 6 7 
NoneType: None
2020-10-23 00:49:42,170 - admin - ERROR -scripts.utils - process.returncode:9
NoneType: None
2020-10-23 00:49:42,170 - admin - ERROR -scripts.utils - process.returncode:9
NoneType: None
2020-10-23 00:49:42,479 - admin - ERROR -scripts.utils - scripts:util:exe_script_util:process_id: Fatal error:Unable to execute the script:sh -xv /Users/arjunkumar/Desktop/notes2/pre-prod/front_end/PyDataFlow_Local/PyDataFlow/pydataflow/core/test3.sh, with params:5 6 7 for detail, Please refer to logfile:/Users/arjunkumar/Desktop/notes2/pre-prod/front_end/PyDataFlow_Local/PyDataFlow/pydataflow/logs/2020-10-23/local_test_project/4999_38111_test3_2020-10-23-00:49:40.log 
Traceback (most recent call last):
  File "/Users/arjunkumar/Desktop/notes2/pre-prod/front_end/PyDataFlow_Local/PyDataFlow/pydataflow/scripts/utils.py", line 153, in exe_script_util
    email_notification_job(msg, process_id, **Jobflowdetail_d)
  File "/Users/arjunkumar/Desktop/notes2/pre-prod/front_end/PyDataFlow_Local/PyDataFlow/pydataflow/meta/utils.py", line 928, in email_notification_job
    send_mail_func(subject, message, from_email, recipient_list)
  File "/Users/arjunkumar/Desktop/notes2/pre-prod/front_end/PyDataFlow_Local/PyDataFlow/pydataflow/meta/utils.py", line 937, in send_mail_func
    html_message=None)
  File "/Users/arjunkumar/Desktop/notes2/pre-prod/front_end/PyDataFlow_Local/PyDataFlow/lib/python3.7/site-packages/django/core/mail/__init__.py", line 60, in send_mail
    return mail.send()
  File "/Users/arjunkumar/Desktop/notes2/pre-prod/front_end/PyDataFlow_Local/PyDataFlow/lib/python3.7/site-packages/django/core/mail/message.py", line 291, in send
    return self.get_connection(fail_silently).send_messages([self])
  File "/Users/arjunkumar/Desktop/notes2/pre-prod/front_end/PyDataFlow_Local/PyDataFlow/lib/python3.7/site-packages/django/core/mail/backends/smtp.py", line 103, in send_messages
    new_conn_created = self.open()
  File "/Users/arjunkumar/Desktop/notes2/pre-prod/front_end/PyDataFlow_Local/PyDataFlow/lib/python3.7/site-packages/django/core/mail/backends/smtp.py", line 63, in open
    self.connection = self.connection_class(self.host, self.port, **connection_params)
  File "/usr/local/Cellar/python/3.7.6_1/Frameworks/Python.framework/Versions/3.7/lib/python3.7/smtplib.py", line 251, in __init__
    (code, msg) = self.connect(host, port)
  File "/usr/local/Cellar/python/3.7.6_1/Frameworks/Python.framework/Versions/3.7/lib/python3.7/smtplib.py", line 336, in connect
    self.sock = self._get_socket(host, port, self.timeout)
  File "/usr/local/Cellar/python/3.7.6_1/Frameworks/Python.framework/Versions/3.7/lib/python3.7/smtplib.py", line 307, in _get_socket
    self.source_address)
  File "/usr/local/Cellar/python/3.7.6_1/Frameworks/Python.framework/Versions/3.7/lib/python3.7/socket.py", line 728, in create_connection
    raise err
  File "/usr/local/Cellar/python/3.7.6_1/Frameworks/Python.framework/Versions/3.7/lib/python3.7/socket.py", line 716, in create_connection
    sock.connect(sa)
ConnectionRefusedError: [Errno 61] Connection refused
2020-10-23 00:49:42,479 - admin - ERROR -scripts.utils - scripts:util:exe_script_util:process_id: Fatal error:Unable to execute the script:sh -xv /Users/arjunkumar/Desktop/notes2/pre-prod/front_end/PyDataFlow_Local/PyDataFlow/pydataflow/core/test3.sh, with params:5 6 7 for detail, Please refer to logfile:/Users/arjunkumar/Desktop/notes2/pre-prod/front_end/PyDataFlow_Local/PyDataFlow/pydataflow/logs/2020-10-23/local_test_project/4999_38111_test3_2020-10-23-00:49:40.log 
Traceback (most recent call last):
  File "/Users/arjunkumar/Desktop/notes2/pre-prod/front_end/PyDataFlow_Local/PyDataFlow/pydataflow/scripts/utils.py", line 153, in exe_script_util
    email_notification_job(msg, process_id, **Jobflowdetail_d)
  File "/Users/arjunkumar/Desktop/notes2/pre-prod/front_end/PyDataFlow_Local/PyDataFlow/pydataflow/meta/utils.py", line 928, in email_notification_job
    send_mail_func(subject, message, from_email, recipient_list)
  File "/Users/arjunkumar/Desktop/notes2/pre-prod/front_end/PyDataFlow_Local/PyDataFlow/pydataflow/meta/utils.py", line 937, in send_mail_func
    html_message=None)
  File "/Users/arjunkumar/Desktop/notes2/pre-prod/front_end/PyDataFlow_Local/PyDataFlow/lib/python3.7/site-packages/django/core/mail/__init__.py", line 60, in send_mail
    return mail.send()
  File "/Users/arjunkumar/Desktop/notes2/pre-prod/front_end/PyDataFlow_Local/PyDataFlow/lib/python3.7/site-packages/django/core/mail/message.py", line 291, in send
    return self.get_connection(fail_silently).send_messages([self])
  File "/Users/arjunkumar/Desktop/notes2/pre-prod/front_end/PyDataFlow_Local/PyDataFlow/lib/python3.7/site-packages/django/core/mail/backends/smtp.py", line 103, in send_messages
    new_conn_created = self.open()
  File "/Users/arjunkumar/Desktop/notes2/pre-prod/front_end/PyDataFlow_Local/PyDataFlow/lib/python3.7/site-packages/django/core/mail/backends/smtp.py", line 63, in open
    self.connection = self.connection_class(self.host, self.port, **connection_params)
  File "/usr/local/Cellar/python/3.7.6_1/Frameworks/Python.framework/Versions/3.7/lib/python3.7/smtplib.py", line 251, in __init__
    (code, msg) = self.connect(host, port)
  File "/usr/local/Cellar/python/3.7.6_1/Frameworks/Python.framework/Versions/3.7/lib/python3.7/smtplib.py", line 336, in connect
    self.sock = self._get_socket(host, port, self.timeout)
  File "/usr/local/Cellar/python/3.7.6_1/Frameworks/Python.framework/Versions/3.7/lib/python3.7/smtplib.py", line 307, in _get_socket
    self.source_address)
  File "/usr/local/Cellar/python/3.7.6_1/Frameworks/Python.framework/Versions/3.7/lib/python3.7/socket.py", line 728, in create_connection
    raise err
  File "/usr/local/Cellar/python/3.7.6_1/Frameworks/Python.framework/Versions/3.7/lib/python3.7/socket.py", line 716, in create_connection
    sock.connect(sa)
ConnectionRefusedError: [Errno 61] Connection refused
2020-10-23 00:49:42,479 - admin - ERROR -scripts.utils - scripts:util:exe_script_util:process_id: Fatal error:Unable to execute the script:sh -xv /Users/arjunkumar/Desktop/notes2/pre-prod/front_end/PyDataFlow_Local/PyDataFlow/pydataflow/core/test3.sh, with params:5 6 7 for detail, Please refer to logfile:/Users/arjunkumar/Desktop/notes2/pre-prod/front_end/PyDataFlow_Local/PyDataFlow/pydataflow/logs/2020-10-23/local_test_project/4999_38111_test3_2020-10-23-00:49:40.log 
Traceback (most recent call last):
  File "/Users/arjunkumar/Desktop/notes2/pre-prod/front_end/PyDataFlow_Local/PyDataFlow/pydataflow/scripts/utils.py", line 153, in exe_script_util
    email_notification_job(msg, process_id, **Jobflowdetail_d)
  File "/Users/arjunkumar/Desktop/notes2/pre-prod/front_end/PyDataFlow_Local/PyDataFlow/pydataflow/meta/utils.py", line 928, in email_notification_job
    send_mail_func(subject, message, from_email, recipient_list)
  File "/Users/arjunkumar/Desktop/notes2/pre-prod/front_end/PyDataFlow_Local/PyDataFlow/pydataflow/meta/utils.py", line 937, in send_mail_func
    html_message=None)
  File "/Users/arjunkumar/Desktop/notes2/pre-prod/front_end/PyDataFlow_Local/PyDataFlow/lib/python3.7/site-packages/django/core/mail/__init__.py", line 60, in send_mail
    return mail.send()
  File "/Users/arjunkumar/Desktop/notes2/pre-prod/front_end/PyDataFlow_Local/PyDataFlow/lib/python3.7/site-packages/django/core/mail/message.py", line 291, in send
    return self.get_connection(fail_silently).send_messages([self])
  File "/Users/arjunkumar/Desktop/notes2/pre-prod/front_end/PyDataFlow_Local/PyDataFlow/lib/python3.7/site-packages/django/core/mail/backends/smtp.py", line 103, in send_messages
    new_conn_created = self.open()
  File "/Users/arjunkumar/Desktop/notes2/pre-prod/front_end/PyDataFlow_Local/PyDataFlow/lib/python3.7/site-packages/django/core/mail/backends/smtp.py", line 63, in open
    self.connection = self.connection_class(self.host, self.port, **connection_params)
  File "/usr/local/Cellar/python/3.7.6_1/Frameworks/Python.framework/Versions/3.7/lib/python3.7/smtplib.py", line 251, in __init__
    (code, msg) = self.connect(host, port)
  File "/usr/local/Cellar/python/3.7.6_1/Frameworks/Python.framework/Versions/3.7/lib/python3.7/smtplib.py", line 336, in connect
    self.sock = self._get_socket(host, port, self.timeout)
  File "/usr/local/Cellar/python/3.7.6_1/Frameworks/Python.framework/Versions/3.7/lib/python3.7/smtplib.py", line 307, in _get_socket
    self.source_address)
  File "/usr/local/Cellar/python/3.7.6_1/Frameworks/Python.framework/Versions/3.7/lib/python3.7/socket.py", line 728, in create_connection
    raise err
  File "/usr/local/Cellar/python/3.7.6_1/Frameworks/Python.framework/Versions/3.7/lib/python3.7/socket.py", line 716, in create_connection
    sock.connect(sa)
ConnectionRefusedError: [Errno 61] Connection refused
